Workbook

Sheet Ремонт квартир
A1: ПРАЙС-ЛИСТ НА РЕМОНТНЫЕ РАБОТЫ — ГРОДНО 2025 | H1: Курс USD: | I1: 3.05
A2: ⚠️ Синие цены — редактируемые поля. Заполните своими расценками. Столбец F — примечания для сайта.
A3: № | B3: Наименование работ | C3: Ед. изм. | D3: Цена (BYN) | E3: Цена ($) | F3: Примечание для сайта
A4: ПОЛЫ
A5: 1 | B5: Стяжка пола 3-5 см | C5: м² | D5: 18 | E5: =D5/$I$1 -> 5.9016393 | F5: с маяками
A6: 2 | B6: Выравнивание пола до 3 см | C6: м² | D6: 12 | E6: =D6/$I$1 -> 3.9344262
A7: 3 | B7: Укладка ламината | C7: м² | D7: 7 | E7: =D7/$I$1 -> 2.295082 | F7: по диагонали +30%
A8: 4 | B8: Укладка паркетной доски | C8: м² | D8: 10 | E8: =D8/$I$1 -> 3.2786885
A9: 5 | B9: Укладка плитки на пол | C9: м² | D9: 27 | E9: =D9/$I$1 -> 8.852459 | F9: стандартный формат
A10: 6 | B10: Укладка плитки крупноформатной | C10: м² | D10: 36 | E10: =D10/$I$1 -> 11.803279 | F10: от 60×60
A11: 7 | B11: Укладка виниловой плитки | C11: м² | D11: 15 | E11: =D11/$I$1 -> 4.9180328
A12: 8 | B12: Плинтус ПВХ с уголками | C12: м/п | D12: 6 | E12: =D12/$I$1 -> 1.9672131
A13: 9 | B13: Плинтус МДФ/полиуретан без покраски | C13: м/п | D13: 18 | E13: =D13/$I$1 -> 5.9016393
A14: 10 | B14: Плинтус полиуретан с покраской | C14: м/п | D14: 24 | E14: =D14/$I$1 -> 7.8688525
A15: 11 | B15: Гидроизоляция жидкая | C15: м² | D15: 9 | E15: =D15/$I$1 -> 2.9508197
A16: 12 | B16: Грунтовка пола | C16: м² | D16: 1.5 | E16: =D16/$I$1 -> 0.49180328
A17: 13 | B17: Утепление (пенопласт/минвата) | C17: м² | D17: 6 | E17: =D17/$I$1 -> 1.9672131
A18: 14 | B18: Демонтаж напольного покрытия | C18: м² | D18: 6 | E18: =D18/$I$1 -> 1.9672131
A19: СТЕНЫ
A20: 15 | B20: Штукатурка стен до 1 см | C20: м² | D20: 15 | E20: =D20/$I$1 -> 4.9180328 | F20: по маякам
A21: 16 | B21: Штукатурка стен до 2 см | C21: м² | D21: 18 | E21: =D21/$I$1 -> 5.9016393 | F21: по маякам
A22: 17 | B22: Штукатурка стен от 2 см | C22: м² | D22: 21 | E22: =D22/$I$1 -> 6.8852459 | F22: по маякам
A23: 18 | B23: Шпаклёвка под обои | C23: м² | D23: 6 | E23: =D23/$I$1 -> 1.9672131
A24: 19 | B24: Шпаклёвка под покраску | C24: м² | D24: 12 | E24: =D24/$I$1 -> 3.9344262 | F24: 2 слоя + шлифовка
A25: 20 | B25: Покраска стен (2 слоя) | C25: м² | D25: 9 | E25: =D25/$I$1 -> 2.9508197
A26: 21 | B26: Оклейка обоями | C26: м² | D26: 6 | E26: =D26/$I$1 -> 1.9672131 | F26: виниловые/флизелиновые
A27: 22 | B27: Облицовка плиткой стены | C27: м² | D27: 30 | E27: =D27/$I$1 -> 9.8360656
A28: 23 | B28: Декоративная штукатурка | C28: м² | D28: 24 | E28: =D28/$I$1 -> 7.8688525 | F28: от, зависит от типа
A29: 24 | B29: Декоративный камень | C29: м² | D29: 36 | E29: =D29/$I$1 -> 11.803279
A30: 25 | B30: Монтаж гипсокартона (прямой) | C30: м² | D30: 21 | E30: =D30/$I$1 -> 6.8852459 | F30: с каркасом
A31: 26 | B31: Монтаж гипсокартона (криволинейный) | C31: м² | D31: 30 | E31: =D31/$I$1 -> 9.8360656
A32: 27 | B32: Кладка перегородок из блоков | C32: м² | D32: 48 | E32: =D32/$I$1 -> 15.737705
A33: 28 | B33: Армирование стекловолокном/сеткой | C33: м² | D33: 6 | E33: =D33/$I$1 -> 1.9672131
A34: 29 | B34: Установка маяков | C34: м/п | D34: 6 | E34: =D34/$I$1 -> 1.9672131
A35: 30 | B35: Грунтовка стен (1 слой) | C35: м² | D35: 1.5 | E35: =D35/$I$1 -> 0.49180328
A36: 31 | B36: Демонтаж штукатурки/обоев | C36: м² | D36: 6 | E36: =D36/$I$1 -> 1.9672131
A37: ПОТОЛКИ
A38: 32 | B38: Штукатурка потолка до 2 см | C38: м² | D38: 24 | E38: =D38/$I$1 -> 7.8688525 | F38: по маякам
A39: 33 | B39: Шпаклёвка потолка под покраску | C39: м² | D39: 15 | E39: =D39/$I$1 -> 4.9180328
A40: 34 | B40: Покраска потолка (2 слоя) | C40: м² | D40: 9 | E40: =D40/$I$1 -> 2.9508197
...

Sheet Строительство домов
A1: ПРАЙС-ЛИСТ НА СТРОИТЕЛЬСТВО ДОМОВ — ГРОДНО 2025
A2: ⚠️ Синие цены — редактируемые поля. Столбец E привязан к курсу на листе "Ремонт квартир".
A3: № | B3: Наименование работ | C3: Ед. изм. | D3: Цена (BYN) | E3: Цена ($) | F3: Примечание для сайта
A4: ФУНДАМЕНТ
A5: 1 | B5: Разметка и земляные работы | C5: м³ | D5: 30 | E5: =D5/'Ремонт квартир'!$I$1 -> 9.8360656
A6: 2 | B6: Устройство ленточного фундамента | C6: м/п | D6: 90 | E6: =D6/'Ремонт квартир'!$I$1 -> 29.508197 | F6: с армированием
A7: 3 | B7: Устройство монолитной плиты | C7: м² | D7: 60 | E7: =D7/'Ремонт квартир'!$I$1 -> 19.672131 | F7: толщина 200-300 мм
A8: 4 | B8: Устройство свайного фундамента | C8: шт. | D8: 120 | E8: =D8/'Ремонт квартир'!$I$1 -> 39.344262 | F8: свая буронабивная
A9: 5 | B9: Гидроизоляция фундамента | C9: м² | D9: 12 | E9: =D9/'Ремонт квартир'!$I$1 -> 3.9344262
A10: 6 | B10: Утепление фундамента | C10: м² | D10: 18 | E10: =D10/'Ремонт квартир'!$I$1 -> 5.9016393 | F10: ЭППС
A11: 7 | B11: Обратная засыпка | C11: м³ | D11: 12 | E11: =D11/'Ремонт квартир'!$I$1 -> 3.9344262
A12: СТЕНЫ И КЛАДКА
A13: 8 | B13: Кладка газосиликатных блоков | C13: м³ | D13: 60 | E13: =D13/'Ремонт квартир'!$I$1 -> 19.672131
A14: 9 | B14: Кладка керамзитобетонных блоков | C14: м³ | D14: 66 | E14: =D14/'Ремонт квартир'!$I$1 -> 21.639344
A15: 10 | B15: Кладка кирпичная | C15: м³ | D15: 90 | E15: =D15/'Ремонт квартир'!$I$1 -> 29.508197
A16: 11 | B16: Армопояс | C16: м/п | D16: 45 | E16: =D16/'Ремонт квартир'!$I$1 -> 14.754098
A17: 12 | B17: Перемычки оконные/дверные | C17: шт. | D17: 30 | E17: =D17/'Ремонт квартир'!$I$1 -> 9.8360656
A18: 13 | B18: Утепление стен снаружи | C18: м² | D18: 24 | E18: =D18/'Ремонт квартир'!$I$1 -> 7.8688525 | F18: минвата/ЭППС
A19: КРОВЛЯ
A20: 14 | B20: Монтаж стропильной системы | C20: м² | D20: 30 | E20: =D20/'Ремонт квартир'!$I$1 -> 9.8360656
A21: 15 | B21: Монтаж обрешётки | C21: м² | D21: 12 | E21: =D21/'Ремонт квартир'!$I$1 -> 3.9344262
A22: 16 | B22: Укладка металлочерепицы | C22: м² | D22: 18 | E22: =D22/'Ремонт квартир'!$I$1 -> 5.9016393
A23: 17 | B23: Укладка мягкой кровли | C23: м² | D23: 21 | E23: =D23/'Ремонт квартир'!$I$1 -> 6.8852459
A24: 18 | B24: Утепление кровли | C24: м² | D24: 18 | E24: =D24/'Ремонт квартир'!$I$1 -> 5.9016393 | F24: 200 мм минвата
A25: 19 | B25: Подшивка карнизов | C25: м/п | D25: 18 | E25: =D25/'Ремонт квартир'!$I$1 -> 5.9016393
A26: 20 | B26: Водосточная система | C26: м/п | D26: 15 | E26: =D26/'Ремонт квартир'!$I$1 -> 4.9180328
A27: ПЕРЕКРЫТИЯ
A28: 21 | B28: Монтаж деревянного перекрытия | C28: м² | D28: 24 | E28: =D28/'Ремонт квартир'!$I$1 -> 7.8688525
A29: 22 | B29: Монтаж ж/б плит перекрытия | C29: шт. | D29: 120 | E29: =D29/'Ремонт квартир'!$I$1 -> 39.344262 | F29: с краном
A30: 23 | B30: Монолитное перекрытие | C30: м² | D30: 60 | E30: =D30/'Ремонт квартир'!$I$1 -> 19.672131 | F30: с армированием и опалубкой
A31: ПАКЕТНЫЕ ПРЕДЛОЖЕНИЯ (ориентир)
A32: 24 | B32: Каркасный дом — коробка | C32: м² | D32: 700 | E32: =D32/'Ремонт квартир'!$I$1 -> 229.5082 | F32: от, без отделки
A33: 25 | B33: Дом из блоков — коробка | C33: м² | D33: 950 | E33: =D33/'Ремонт квартир'!$I$1 -> 311.47541 | F33: от, без отделки
A34: 26 | B34: Дом из блоков — под ключ | C34: м² | D34: 1800 | E34: =D34/'Ремонт квартир'!$I$1 -> 590.16393 | F34: от, с отделкой
A35: 27 | B35: Кирпичный дом — коробка | C35: м² | D35: 1200 | E35: =D35/'Ремонт квартир'!$I$1 -> 393.44262 | F35: от, без отделки
A36: 28 | B36: Кирпичный дом — под ключ | C36: м² | D36: 2400 | E36: =D36/'Ремонт квартир'!$I$1 -> 786.88525 | F36: от, с отделкой

Sheet Калькулятор для клиента
A1: БЫСТРЫЙ КАЛЬКУЛЯТОР СТОИМОСТИ РЕМОНТА
A2: ⚠️ Заполните жёлтые ячейки — итог рассчитается автоматически
A4: ПАРАМЕТРЫ ОБЪЕКТА
B5: Площадь квартиры, м² | D5: 45
B6: Высота потолков, м | D6: 2.7
B7: Количество комнат | D7: 2
B8: Санузлов | D8: 1
B10: РАСЧЁТНЫЕ ПЛОЩАДИ
B11: Площадь стен (приблиз.), м² | D11: =((D5^0.5)*4*2)*D6 -> 144.8972
B12: Площадь потолка, м² | D12: =D5 -> 45
B13: Площадь пола, м² | D13: =D5 -> 45
A15: № | B15: Работы (типовой набор) | C15: Объём | D15: Цена/ед. | E15: Сумма BYN | F15: Сумма $
A16: 1 | B16: Штукатурка стен до 2 см | C16: =D11 -> 144.8972 | D16: 18 | E16: =C16*D16 -> 2608.1497 | F16: =E16/'Ремонт квартир'!$I$1 -> 855.13105
A17: 2 | B17: Шпаклёвка стен под покраску | C17: =D11 -> 144.8972 | D17: 12 | E17: =C17*D17 -> 1738.7665 | F17: =E17/'Ремонт квартир'!$I$1 -> 570.08736
A18: 3 | B18: Покраска стен (2 слоя) | C18: =D11 -> 144.8972 | D18: 9 | E18: =C18*D18 -> 1304.0748 | F18: =E18/'Ремонт квартир'!$I$1 -> 427.56552
A19: 4 | B19: Стяжка пола 3-5 см | C19: =D13 -> 45 | D19: 18 | E19: =C19*D19 -> 810 | F19: =E19/'Ремонт квартир'!$I$1 -> 265.57377
A20: 5 | B20: Укладка ламината | C20: =D13 -> 45 | D20: 7 | E20: =C20*D20 -> 315 | F20: =E20/'Ремонт квартир'!$I$1 -> 103.27869
A21: 6 | B21: Шпаклёвка потолка | C21: =D12 -> 45 | D21: 15 | E21: =C21*D21 -> 675 | F21: =E21/'Ремонт квартир'!$I$1 -> 221.31148
A22: 7 | B22: Покраска потолка | C22: =D12 -> 45 | D22: 9 | E22: =C22*D22 -> 405 | F22: =E22/'Ремонт квартир'!$I$1 -> 132.78689
A23: 8 | B23: Электрика (10 точек) | C23: 10 | D23: 30 | E23: =C23*D23 -> 300 | F23: =E23/'Ремонт квартир'!$I$1 -> 98.360656
A24: 9 | B24: Сантехника (базовый комплект) | C24: 1 | D24: 360 | E24: =C24*D24 -> 360 | F24: =E24/'Ремонт квартир'!$I$1 -> 118.03279
A25: 10 | B25: Межкомнатные двери | C25: =D7 -> 2 | D25: 90 | E25: =C25*D25 -> 180 | F25: =E25/'Ремонт квартир'!$I$1 -> 59.016393
A26: ИТОГО РАБОТЫ: | E26: =SUM(E16:E25) -> 8695.991 | F26: =E26/'Ремонт квартир'!$I$1 -> 2851.1446
B27: Наценка компании (%): | D27: 0.35
A28: ИТОГО С НАЦЕНКОЙ: | E28: =E26*(1+D27) -> 11739.588 | F28: =E28/'Ремонт квартир'!$I$1 -> 3849.0452
